import { render, screen } from '@testing-library/react';
import ErrorBoundary from '../../src/components/ErrorBoundary';
import { vi } from 'vitest';

// Mock component that throws an error
const ThrowError = () => {
  throw new Error('Test error');
  return null;
};

describe('ErrorBoundary', () => {
  // Prevent console.error from cluttering test output
  const originalError = console.error;
  beforeAll(() => {
    console.error = vi.fn();
  });

  afterAll(() => {
    console.error = originalError;
  });

  it('renders children when no error occurs', () => {
    render(
      <ErrorBoundary>
        <div>Test Content</div>
      </ErrorBoundary>
    );

    expect(screen.getByText('Test Content')).toBeInTheDocument();
  });

  it('renders fallback UI when error occurs', () => {
    render(
      <ErrorBoundary>
        <ThrowError />
      </ErrorBoundary>
    );

    expect(screen.getByText(/something went wrong/i)).toBeInTheDocument();
  });

  it('renders custom fallback when provided', () => {
    render(
      <ErrorBoundary fallback={<div>Custom Error UI</div>}>
        <ThrowError />
      </ErrorBoundary>
    );

    expect(screen.getByText('Custom Error UI')).toBeInTheDocument();
  });
}); 